[2025-04-24 10:53:53,366] 97 werkzeug - WARNING -  * Debugger is active!
[2025-04-24 10:53:53,369] 97 werkzeug - INFO -  * Debugger PIN: 687-007-829
[2025-04-24 10:54:12,402] 97 werkzeug - INFO - 127.0.0.1 - - [24/Apr/2025 10:54:12] "GET / HTTP/1.1" 200 -
[2025-04-24 10:54:12,472] 97 werkzeug - INFO - 127.0.0.1 - - [24/Apr/2025 10:54:12] "[33mGET /api/placeholder/1200/400 HTTP/1.1[0m" 404 -
[2025-04-24 10:54:12,924] 97 werkzeug - INFO - 127.0.0.1 - - [24/Apr/2025 10:54:12] "[33mGET /favicon.ico HTTP/1.1[0m" 404 -
[2025-04-24 10:55:18,356] 74 root - INFO - predictions completed. 
[2025-04-24 10:55:18,440] 97 werkzeug - INFO - 127.0.0.1 - - [24/Apr/2025 10:55:18] "POST /predict HTTP/1.1" 200 -
[2025-04-24 13:08:36,250] 97 werkzeug - INFO - 127.0.0.1 - - [24/Apr/2025 13:08:36] "GET / HTTP/1.1" 200 -
[2025-04-24 13:08:36,340] 97 werkzeug - INFO - 127.0.0.1 - - [24/Apr/2025 13:08:36] "[33mGET /api/placeholder/1200/400 HTTP/1.1[0m" 404 -
[2025-04-24 13:09:06,259] 74 root - INFO - predictions completed. 
[2025-04-24 13:09:06,301] 97 werkzeug - INFO - 127.0.0.1 - - [24/Apr/2025 13:09:06] "POST /predict HTTP/1.1" 200 -
[2025-04-24 13:09:11,066] 97 werkzeug - INFO - 127.0.0.1 - - [24/Apr/2025 13:09:11] "GET /download_results HTTP/1.1" 200 -
[2025-04-24 13:15:49,704] 97 werkzeug - INFO - 127.0.0.1 - - [24/Apr/2025 13:15:49] "GET / HTTP/1.1" 200 -
[2025-04-24 13:15:49,769] 97 werkzeug - INFO - 127.0.0.1 - - [24/Apr/2025 13:15:49] "[33mGET /api/placeholder/1200/400 HTTP/1.1[0m" 404 -
[2025-04-24 13:15:58,321] 97 werkzeug - INFO - 127.0.0.1 - - [24/Apr/2025 13:15:58] "GET / HTTP/1.1" 200 -
[2025-04-24 13:15:58,364] 97 werkzeug - INFO - 127.0.0.1 - - [24/Apr/2025 13:15:58] "[33mGET /api/placeholder/1200/400 HTTP/1.1[0m" 404 -
[2025-04-29 01:17:11,219] 97 werkzeug - INFO - 127.0.0.1 - - [29/Apr/2025 01:17:11] "GET / HTTP/1.1" 200 -
[2025-04-29 01:17:11,351] 97 werkzeug - INFO - 127.0.0.1 - - [29/Apr/2025 01:17:11] "[33mGET /api/placeholder/1200/400 HTTP/1.1[0m" 404 -
[2025-04-29 01:17:12,055] 97 werkzeug - INFO - 127.0.0.1 - - [29/Apr/2025 01:17:12] "[33mGET /favicon.ico HTTP/1.1[0m" 404 -
[2025-04-29 01:17:30,339] 74 root - INFO - predictions completed. 
[2025-04-29 01:17:30,384] 97 werkzeug - INFO - 127.0.0.1 - - [29/Apr/2025 01:17:30] "POST /predict HTTP/1.1" 200 -
[2025-04-29 01:17:38,078] 97 werkzeug - INFO - 127.0.0.1 - - [29/Apr/2025 01:17:38] "GET /download_results HTTP/1.1" 200 -
[2025-04-29 12:18:29,777] 97 werkzeug - INFO - 127.0.0.1 - - [29/Apr/2025 12:18:29] "GET / HTTP/1.1" 200 -
[2025-04-29 12:18:29,902] 97 werkzeug - INFO - 127.0.0.1 - - [29/Apr/2025 12:18:29] "[33mGET /api/placeholder/1200/400 HTTP/1.1[0m" 404 -
[2025-04-29 12:18:30,015] 97 werkzeug - INFO - 127.0.0.1 - - [29/Apr/2025 12:18:30] "[33mGET /favicon.ico HTTP/1.1[0m" 404 -
[2025-04-29 12:32:41,887] 97 werkzeug - INFO - 127.0.0.1 - - [29/Apr/2025 12:32:41] "GET / HTTP/1.1" 200 -
[2025-04-29 12:32:42,278] 97 werkzeug - INFO - 127.0.0.1 - - [29/Apr/2025 12:32:42] "[33mGET /api/placeholder/1200/400 HTTP/1.1[0m" 404 -
[2025-04-29 12:33:03,786] 74 root - INFO - predictions completed. 
[2025-04-29 12:33:03,882] 97 werkzeug - INFO - 127.0.0.1 - - [29/Apr/2025 12:33:03] "POST /predict HTTP/1.1" 200 -
[2025-04-29 12:33:12,599] 97 werkzeug - INFO - 127.0.0.1 - - [29/Apr/2025 12:33:12] "GET /download_results HTTP/1.1" 200 -
[2025-04-29 12:33:25,405] 97 werkzeug - INFO - 127.0.0.1 - - [29/Apr/2025 12:33:25] "GET / HTTP/1.1" 200 -
[2025-04-29 12:33:25,641] 97 werkzeug - INFO - 127.0.0.1 - - [29/Apr/2025 12:33:25] "[33mGET /api/placeholder/1200/400 HTTP/1.1[0m" 404 -
[2025-04-29 12:33:47,746] 74 root - INFO - predictions completed. 
[2025-04-29 12:33:47,906] 97 werkzeug - INFO - 127.0.0.1 - - [29/Apr/2025 12:33:47] "POST /predict HTTP/1.1" 200 -
[2025-04-29 12:33:55,773] 97 werkzeug - INFO - 127.0.0.1 - - [29/Apr/2025 12:33:55] "GET /download_results HTTP/1.1" 200 -
[2025-04-29 13:11:55,217] 97 werkzeug - INFO - 127.0.0.1 - - [29/Apr/2025 13:11:55] "GET / HTTP/1.1" 200 -
[2025-04-29 13:11:55,292] 97 werkzeug - INFO - 127.0.0.1 - - [29/Apr/2025 13:11:55] "[33mGET /api/placeholder/1200/400 HTTP/1.1[0m" 404 -
[2025-04-29 13:12:06,538] 74 root - INFO - predictions completed. 
[2025-04-29 13:12:06,607] 97 werkzeug - INFO - 127.0.0.1 - - [29/Apr/2025 13:12:06] "POST /predict HTTP/1.1" 200 -
[2025-04-29 13:12:08,035] 97 werkzeug - INFO - 127.0.0.1 - - [29/Apr/2025 13:12:08] "GET /download_results HTTP/1.1" 200 -
[2025-04-29 13:14:56,966] 97 werkzeug - INFO - 127.0.0.1 - - [29/Apr/2025 13:14:56] "GET / HTTP/1.1" 200 -
[2025-04-29 13:14:57,083] 97 werkzeug - INFO - 127.0.0.1 - - [29/Apr/2025 13:14:57] "[33mGET /api/placeholder/1200/400 HTTP/1.1[0m" 404 -
[2025-04-29 13:15:11,019] 40 root - INFO - Error in prediction_pipeline_main
[2025-04-29 13:15:11,024] 84 root - ERROR - An error occurred during prediction.
Traceback (most recent call last):
  File "C:\Users\ma230\Desktop\Wafer-Sensor-Fault-Detection-System-main\src\pipelines\prediction_pipeline.py", line 36, in save_input_files
    input_csv_file.save(pred_file_path)
  File "C:\Users\ma230\AppData\Local\Programs\Python\Python311\Lib\site-packages\werkzeug\datastructures\file_storage.py", line 129, in save
    dst = open(dst, "wb")
          ^^^^^^^^^^^^^^^
PermissionError: [Errno 13] Permission denied: 'prediction_artifacts\\input__.csv'

During handling of the above exception, another exception occurred:

Traceback (most recent call last):
  File "C:\Users\ma230\Desktop\Wafer-Sensor-Fault-Detection-System-main\src\pipelines\prediction_pipeline.py", line 81, in run_pipeline
    input_csv_path = self.save_input_files()
                     ^^^^^^^^^^^^^^^^^^^^^^^
  File "C:\Users\ma230\Desktop\Wafer-Sensor-Fault-Detection-System-main\src\pipelines\prediction_pipeline.py", line 41, in save_input_files
    raise CustomException(e,sys)
src.exception.CustomException: Error occured in python script [C:\Users\ma230\Desktop\Wafer-Sensor-Fault-Detection-System-main\src\pipelines\prediction_pipeline.py] line number [36] error message[[Errno 13] Permission denied: 'prediction_artifacts\\input__.csv']

During handling of the above exception, another exception occurred:

Traceback (most recent call last):
  File "C:\Users\ma230\Desktop\Wafer-Sensor-Fault-Detection-System-main\application.py", line 30, in upload
    prediction_file_detail = pipeline.run_pipeline()
                             ^^^^^^^^^^^^^^^^^^^^^^^
  File "C:\Users\ma230\Desktop\Wafer-Sensor-Fault-Detection-System-main\src\pipelines\prediction_pipeline.py", line 88, in run_pipeline
    raise CustomException(e,sys)
src.exception.CustomException: Error occured in python script [C:\Users\ma230\Desktop\Wafer-Sensor-Fault-Detection-System-main\src\pipelines\prediction_pipeline.py] line number [81] error message[Error occured in python script [C:\Users\ma230\Desktop\Wafer-Sensor-Fault-Detection-System-main\src\pipelines\prediction_pipeline.py] line number [36] error message[[Errno 13] Permission denied: 'prediction_artifacts\\input__.csv']]
[2025-04-29 13:15:11,445] 97 werkzeug - INFO - 127.0.0.1 - - [29/Apr/2025 13:15:11] "[35m[1mPOST /predict HTTP/1.1[0m" 500 -
[2025-04-29 13:15:11,558] 97 werkzeug - INFO - 127.0.0.1 - - [29/Apr/2025 13:15:11] "GET /predict?__debugger__=yes&cmd=resource&f=style.css HTTP/1.1" 200 -
[2025-04-29 13:15:11,590] 97 werkzeug - INFO - 127.0.0.1 - - [29/Apr/2025 13:15:11] "GET /predict?__debugger__=yes&cmd=resource&f=debugger.js HTTP/1.1" 200 -
[2025-04-29 13:15:11,621] 97 werkzeug - INFO - 127.0.0.1 - - [29/Apr/2025 13:15:11] "GET /predict?__debugger__=yes&cmd=resource&f=console.png&s=itetznEd7CT4GSRpnRXn HTTP/1.1" 200 -
[2025-04-29 13:15:11,857] 97 werkzeug - INFO - 127.0.0.1 - - [29/Apr/2025 13:15:11] "GET /predict?__debugger__=yes&cmd=resource&f=console.png HTTP/1.1" 200 -
[2025-04-29 13:15:17,222] 40 root - INFO - Error in prediction_pipeline_main
[2025-04-29 13:15:17,222] 84 root - ERROR - An error occurred during prediction.
Traceback (most recent call last):
  File "C:\Users\ma230\Desktop\Wafer-Sensor-Fault-Detection-System-main\src\pipelines\prediction_pipeline.py", line 36, in save_input_files
    input_csv_file.save(pred_file_path)
  File "C:\Users\ma230\AppData\Local\Programs\Python\Python311\Lib\site-packages\werkzeug\datastructures\file_storage.py", line 129, in save
    dst = open(dst, "wb")
          ^^^^^^^^^^^^^^^
PermissionError: [Errno 13] Permission denied: 'prediction_artifacts\\input__.csv'

During handling of the above exception, another exception occurred:

Traceback (most recent call last):
  File "C:\Users\ma230\Desktop\Wafer-Sensor-Fault-Detection-System-main\src\pipelines\prediction_pipeline.py", line 81, in run_pipeline
    input_csv_path = self.save_input_files()
                     ^^^^^^^^^^^^^^^^^^^^^^^
  File "C:\Users\ma230\Desktop\Wafer-Sensor-Fault-Detection-System-main\src\pipelines\prediction_pipeline.py", line 41, in save_input_files
    raise CustomException(e,sys)
src.exception.CustomException: Error occured in python script [C:\Users\ma230\Desktop\Wafer-Sensor-Fault-Detection-System-main\src\pipelines\prediction_pipeline.py] line number [36] error message[[Errno 13] Permission denied: 'prediction_artifacts\\input__.csv']

During handling of the above exception, another exception occurred:

Traceback (most recent call last):
  File "C:\Users\ma230\Desktop\Wafer-Sensor-Fault-Detection-System-main\application.py", line 30, in upload
    prediction_file_detail = pipeline.run_pipeline()
                             ^^^^^^^^^^^^^^^^^^^^^^^
  File "C:\Users\ma230\Desktop\Wafer-Sensor-Fault-Detection-System-main\src\pipelines\prediction_pipeline.py", line 88, in run_pipeline
    raise CustomException(e,sys)
src.exception.CustomException: Error occured in python script [C:\Users\ma230\Desktop\Wafer-Sensor-Fault-Detection-System-main\src\pipelines\prediction_pipeline.py] line number [81] error message[Error occured in python script [C:\Users\ma230\Desktop\Wafer-Sensor-Fault-Detection-System-main\src\pipelines\prediction_pipeline.py] line number [36] error message[[Errno 13] Permission denied: 'prediction_artifacts\\input__.csv']]
[2025-04-29 13:15:17,250] 97 werkzeug - INFO - 127.0.0.1 - - [29/Apr/2025 13:15:17] "[35m[1mPOST /predict HTTP/1.1[0m" 500 -
[2025-04-29 13:15:17,287] 97 werkzeug - INFO - 127.0.0.1 - - [29/Apr/2025 13:15:17] "[36mGET /predict?__debugger__=yes&cmd=resource&f=style.css HTTP/1.1[0m" 304 -
[2025-04-29 13:15:17,297] 97 werkzeug - INFO - 127.0.0.1 - - [29/Apr/2025 13:15:17] "[36mGET /predict?__debugger__=yes&cmd=resource&f=debugger.js HTTP/1.1[0m" 304 -
[2025-04-29 13:15:17,330] 97 werkzeug - INFO - 127.0.0.1 - - [29/Apr/2025 13:15:17] "[36mGET /predict?__debugger__=yes&cmd=resource&f=console.png&s=itetznEd7CT4GSRpnRXn HTTP/1.1[0m" 304 -
[2025-04-29 13:15:25,703] 97 werkzeug - INFO - 127.0.0.1 - - [29/Apr/2025 13:15:25] "GET / HTTP/1.1" 200 -
[2025-04-29 13:15:25,780] 97 werkzeug - INFO - 127.0.0.1 - - [29/Apr/2025 13:15:25] "[33mGET /api/placeholder/1200/400 HTTP/1.1[0m" 404 -
[2025-04-29 13:15:42,295] 40 root - INFO - Error in prediction_pipeline_main
[2025-04-29 13:15:42,295] 84 root - ERROR - An error occurred during prediction.
Traceback (most recent call last):
  File "C:\Users\ma230\Desktop\Wafer-Sensor-Fault-Detection-System-main\src\pipelines\prediction_pipeline.py", line 36, in save_input_files
    input_csv_file.save(pred_file_path)
  File "C:\Users\ma230\AppData\Local\Programs\Python\Python311\Lib\site-packages\werkzeug\datastructures\file_storage.py", line 129, in save
    dst = open(dst, "wb")
          ^^^^^^^^^^^^^^^
PermissionError: [Errno 13] Permission denied: 'prediction_artifacts\\input__.csv'

During handling of the above exception, another exception occurred:

Traceback (most recent call last):
  File "C:\Users\ma230\Desktop\Wafer-Sensor-Fault-Detection-System-main\src\pipelines\prediction_pipeline.py", line 81, in run_pipeline
    input_csv_path = self.save_input_files()
                     ^^^^^^^^^^^^^^^^^^^^^^^
  File "C:\Users\ma230\Desktop\Wafer-Sensor-Fault-Detection-System-main\src\pipelines\prediction_pipeline.py", line 41, in save_input_files
    raise CustomException(e,sys)
src.exception.CustomException: Error occured in python script [C:\Users\ma230\Desktop\Wafer-Sensor-Fault-Detection-System-main\src\pipelines\prediction_pipeline.py] line number [36] error message[[Errno 13] Permission denied: 'prediction_artifacts\\input__.csv']

During handling of the above exception, another exception occurred:

Traceback (most recent call last):
  File "C:\Users\ma230\Desktop\Wafer-Sensor-Fault-Detection-System-main\application.py", line 30, in upload
    prediction_file_detail = pipeline.run_pipeline()
                             ^^^^^^^^^^^^^^^^^^^^^^^
  File "C:\Users\ma230\Desktop\Wafer-Sensor-Fault-Detection-System-main\src\pipelines\prediction_pipeline.py", line 88, in run_pipeline
    raise CustomException(e,sys)
src.exception.CustomException: Error occured in python script [C:\Users\ma230\Desktop\Wafer-Sensor-Fault-Detection-System-main\src\pipelines\prediction_pipeline.py] line number [81] error message[Error occured in python script [C:\Users\ma230\Desktop\Wafer-Sensor-Fault-Detection-System-main\src\pipelines\prediction_pipeline.py] line number [36] error message[[Errno 13] Permission denied: 'prediction_artifacts\\input__.csv']]
[2025-04-29 13:15:42,331] 97 werkzeug - INFO - 127.0.0.1 - - [29/Apr/2025 13:15:42] "[35m[1mPOST /predict HTTP/1.1[0m" 500 -
[2025-04-29 13:15:42,373] 97 werkzeug - INFO - 127.0.0.1 - - [29/Apr/2025 13:15:42] "[36mGET /predict?__debugger__=yes&cmd=resource&f=style.css HTTP/1.1[0m" 304 -
[2025-04-29 13:15:42,379] 97 werkzeug - INFO - 127.0.0.1 - - [29/Apr/2025 13:15:42] "[36mGET /predict?__debugger__=yes&cmd=resource&f=debugger.js HTTP/1.1[0m" 304 -
[2025-04-29 13:15:42,448] 97 werkzeug - INFO - 127.0.0.1 - - [29/Apr/2025 13:15:42] "[36mGET /predict?__debugger__=yes&cmd=resource&f=console.png&s=itetznEd7CT4GSRpnRXn HTTP/1.1[0m" 304 -
[2025-04-29 13:17:13,431] 97 werkzeug - INFO - 127.0.0.1 - - [29/Apr/2025 13:17:13] "GET / HTTP/1.1" 200 -
[2025-04-29 13:17:13,511] 97 werkzeug - INFO - 127.0.0.1 - - [29/Apr/2025 13:17:13] "[33mGET /api/placeholder/1200/400 HTTP/1.1[0m" 404 -
[2025-04-29 13:17:23,803] 40 root - INFO - Error in prediction_pipeline_main
[2025-04-29 13:17:23,803] 84 root - ERROR - An error occurred during prediction.
Traceback (most recent call last):
  File "C:\Users\ma230\Desktop\Wafer-Sensor-Fault-Detection-System-main\src\pipelines\prediction_pipeline.py", line 36, in save_input_files
    input_csv_file.save(pred_file_path)
  File "C:\Users\ma230\AppData\Local\Programs\Python\Python311\Lib\site-packages\werkzeug\datastructures\file_storage.py", line 129, in save
    dst = open(dst, "wb")
          ^^^^^^^^^^^^^^^
PermissionError: [Errno 13] Permission denied: 'prediction_artifacts\\input__.csv'

During handling of the above exception, another exception occurred:

Traceback (most recent call last):
  File "C:\Users\ma230\Desktop\Wafer-Sensor-Fault-Detection-System-main\src\pipelines\prediction_pipeline.py", line 81, in run_pipeline
    input_csv_path = self.save_input_files()
                     ^^^^^^^^^^^^^^^^^^^^^^^
  File "C:\Users\ma230\Desktop\Wafer-Sensor-Fault-Detection-System-main\src\pipelines\prediction_pipeline.py", line 41, in save_input_files
    raise CustomException(e,sys)
src.exception.CustomException: Error occured in python script [C:\Users\ma230\Desktop\Wafer-Sensor-Fault-Detection-System-main\src\pipelines\prediction_pipeline.py] line number [36] error message[[Errno 13] Permission denied: 'prediction_artifacts\\input__.csv']

During handling of the above exception, another exception occurred:

Traceback (most recent call last):
  File "C:\Users\ma230\Desktop\Wafer-Sensor-Fault-Detection-System-main\application.py", line 30, in upload
    prediction_file_detail = pipeline.run_pipeline()
                             ^^^^^^^^^^^^^^^^^^^^^^^
  File "C:\Users\ma230\Desktop\Wafer-Sensor-Fault-Detection-System-main\src\pipelines\prediction_pipeline.py", line 88, in run_pipeline
    raise CustomException(e,sys)
src.exception.CustomException: Error occured in python script [C:\Users\ma230\Desktop\Wafer-Sensor-Fault-Detection-System-main\src\pipelines\prediction_pipeline.py] line number [81] error message[Error occured in python script [C:\Users\ma230\Desktop\Wafer-Sensor-Fault-Detection-System-main\src\pipelines\prediction_pipeline.py] line number [36] error message[[Errno 13] Permission denied: 'prediction_artifacts\\input__.csv']]
[2025-04-29 13:17:23,836] 97 werkzeug - INFO - 127.0.0.1 - - [29/Apr/2025 13:17:23] "[35m[1mPOST /predict HTTP/1.1[0m" 500 -
[2025-04-29 13:17:23,865] 97 werkzeug - INFO - 127.0.0.1 - - [29/Apr/2025 13:17:23] "[36mGET /predict?__debugger__=yes&cmd=resource&f=style.css HTTP/1.1[0m" 304 -
[2025-04-29 13:17:23,875] 97 werkzeug - INFO - 127.0.0.1 - - [29/Apr/2025 13:17:23] "[36mGET /predict?__debugger__=yes&cmd=resource&f=debugger.js HTTP/1.1[0m" 304 -
[2025-04-29 13:17:23,942] 97 werkzeug - INFO - 127.0.0.1 - - [29/Apr/2025 13:17:23] "[36mGET /predict?__debugger__=yes&cmd=resource&f=console.png&s=itetznEd7CT4GSRpnRXn HTTP/1.1[0m" 304 -
[2025-04-29 13:18:35,636] 97 werkzeug - INFO - 127.0.0.1 - - [29/Apr/2025 13:18:35] "GET / HTTP/1.1" 200 -
[2025-04-29 13:18:35,839] 97 werkzeug - INFO - 127.0.0.1 - - [29/Apr/2025 13:18:35] "[33mGET /api/placeholder/1200/400 HTTP/1.1[0m" 404 -
[2025-04-29 13:18:43,063] 40 root - INFO - Error in prediction_pipeline_main
[2025-04-29 13:18:43,064] 84 root - ERROR - An error occurred during prediction.
Traceback (most recent call last):
  File "C:\Users\ma230\Desktop\Wafer-Sensor-Fault-Detection-System-main\src\pipelines\prediction_pipeline.py", line 36, in save_input_files
    input_csv_file.save(pred_file_path)
  File "C:\Users\ma230\AppData\Local\Programs\Python\Python311\Lib\site-packages\werkzeug\datastructures\file_storage.py", line 129, in save
    dst = open(dst, "wb")
          ^^^^^^^^^^^^^^^
PermissionError: [Errno 13] Permission denied: 'prediction_artifacts\\input__.csv'

During handling of the above exception, another exception occurred:

Traceback (most recent call last):
  File "C:\Users\ma230\Desktop\Wafer-Sensor-Fault-Detection-System-main\src\pipelines\prediction_pipeline.py", line 81, in run_pipeline
    input_csv_path = self.save_input_files()
                     ^^^^^^^^^^^^^^^^^^^^^^^
  File "C:\Users\ma230\Desktop\Wafer-Sensor-Fault-Detection-System-main\src\pipelines\prediction_pipeline.py", line 41, in save_input_files
    raise CustomException(e,sys)
src.exception.CustomException: Error occured in python script [C:\Users\ma230\Desktop\Wafer-Sensor-Fault-Detection-System-main\src\pipelines\prediction_pipeline.py] line number [36] error message[[Errno 13] Permission denied: 'prediction_artifacts\\input__.csv']

During handling of the above exception, another exception occurred:

Traceback (most recent call last):
  File "C:\Users\ma230\Desktop\Wafer-Sensor-Fault-Detection-System-main\application.py", line 30, in upload
    prediction_file_detail = pipeline.run_pipeline()
                             ^^^^^^^^^^^^^^^^^^^^^^^
  File "C:\Users\ma230\Desktop\Wafer-Sensor-Fault-Detection-System-main\src\pipelines\prediction_pipeline.py", line 88, in run_pipeline
    raise CustomException(e,sys)
src.exception.CustomException: Error occured in python script [C:\Users\ma230\Desktop\Wafer-Sensor-Fault-Detection-System-main\src\pipelines\prediction_pipeline.py] line number [81] error message[Error occured in python script [C:\Users\ma230\Desktop\Wafer-Sensor-Fault-Detection-System-main\src\pipelines\prediction_pipeline.py] line number [36] error message[[Errno 13] Permission denied: 'prediction_artifacts\\input__.csv']]
[2025-04-29 13:18:43,095] 97 werkzeug - INFO - 127.0.0.1 - - [29/Apr/2025 13:18:43] "[35m[1mPOST /predict HTTP/1.1[0m" 500 -
[2025-04-29 13:18:43,232] 97 werkzeug - INFO - 127.0.0.1 - - [29/Apr/2025 13:18:43] "GET /predict?__debugger__=yes&cmd=resource&f=style.css HTTP/1.1" 200 -
[2025-04-29 13:18:43,236] 97 werkzeug - INFO - 127.0.0.1 - - [29/Apr/2025 13:18:43] "GET /predict?__debugger__=yes&cmd=resource&f=debugger.js HTTP/1.1" 200 -
[2025-04-29 13:18:43,409] 97 werkzeug - INFO - 127.0.0.1 - - [29/Apr/2025 13:18:43] "GET /predict?__debugger__=yes&cmd=resource&f=console.png&s=itetznEd7CT4GSRpnRXn HTTP/1.1" 200 -
[2025-04-29 13:18:43,470] 97 werkzeug - INFO - 127.0.0.1 - - [29/Apr/2025 13:18:43] "GET /predict?__debugger__=yes&cmd=resource&f=console.png HTTP/1.1" 200 -
